2020-09-04 15:22:56,881 INFO: Work_on_ship startup [in /home/andrii/PycharmProjects/work_on_ship/app/__init__.py:46]
2020-09-04 15:25:31,991 INFO: Work_on_ship startup [in /home/andrii/PycharmProjects/work_on_ship/app/__init__.py:46]
2020-09-04 15:55:24,927 INFO: Work_on_ship startup [in /home/andrii/PycharmProjects/work_on_ship/app/__init__.py:46]
2020-09-04 15:58:21,438 INFO: Work_on_ship startup [in /home/andrii/PycharmProjects/work_on_ship/app/__init__.py:46]
2020-09-04 17:46:09,689 INFO: Work_on_ship startup [in /home/andrii/PycharmProjects/work_on_ship/app/__init__.py:46]
2020-09-04 17:46:42,071 ERROR: Exception on /index [POST] [in /home/andrii/PycharmProjects/work_on_ship/venv/lib/python3.8/site-packages/flask/app.py:1891]
Traceback (most recent call last):
  File "/home/andrii/PycharmProjects/work_on_ship/venv/lib/python3.8/site-packages/flask/app.py", line 2447, in wsgi_app
    response = self.full_dispatch_request()
  File "/home/andrii/PycharmProjects/work_on_ship/venv/lib/python3.8/site-packages/flask/app.py", line 1952, in full_dispatch_request
    rv = self.handle_user_exception(e)
  File "/home/andrii/PycharmProjects/work_on_ship/venv/lib/python3.8/site-packages/flask/app.py", line 1821, in handle_user_exception
    reraise(exc_type, exc_value, tb)
  File "/home/andrii/PycharmProjects/work_on_ship/venv/lib/python3.8/site-packages/flask/_compat.py", line 39, in reraise
    raise value
  File "/home/andrii/PycharmProjects/work_on_ship/venv/lib/python3.8/site-packages/flask/app.py", line 1950, in full_dispatch_request
    rv = self.dispatch_request()
  File "/home/andrii/PycharmProjects/work_on_ship/venv/lib/python3.8/site-packages/flask/app.py", line 1936, in dispatch_request
    return self.view_functions[rule.endpoint](**req.view_args)
  File "/home/andrii/PycharmProjects/work_on_ship/app/routes.py", line 23, in index
    email.send_email(order)
AttributeError: module 'email' has no attribute 'send_email'
2020-09-04 17:55:38,302 ERROR: Exception on /index [POST] [in /home/andrii/PycharmProjects/work_on_ship/venv/lib/python3.8/site-packages/flask/app.py:1891]
Traceback (most recent call last):
  File "/home/andrii/PycharmProjects/work_on_ship/venv/lib/python3.8/site-packages/flask/app.py", line 2447, in wsgi_app
    response = self.full_dispatch_request()
  File "/home/andrii/PycharmProjects/work_on_ship/venv/lib/python3.8/site-packages/flask/app.py", line 1952, in full_dispatch_request
    rv = self.handle_user_exception(e)
  File "/home/andrii/PycharmProjects/work_on_ship/venv/lib/python3.8/site-packages/flask/app.py", line 1821, in handle_user_exception
    reraise(exc_type, exc_value, tb)
  File "/home/andrii/PycharmProjects/work_on_ship/venv/lib/python3.8/site-packages/flask/_compat.py", line 39, in reraise
    raise value
  File "/home/andrii/PycharmProjects/work_on_ship/venv/lib/python3.8/site-packages/flask/app.py", line 1950, in full_dispatch_request
    rv = self.dispatch_request()
  File "/home/andrii/PycharmProjects/work_on_ship/venv/lib/python3.8/site-packages/flask/app.py", line 1936, in dispatch_request
    return self.view_functions[rule.endpoint](**req.view_args)
  File "/home/andrii/PycharmProjects/work_on_ship/app/routes.py", line 23, in index
    email.send_email(order)
AttributeError: module 'email' has no attribute 'send_email'
2020-09-04 17:58:24,627 INFO: Work_on_ship startup [in /home/andrii/PycharmProjects/work_on_ship/app/__init__.py:46]
2020-09-04 17:58:36,084 ERROR: Exception on /index [POST] [in /home/andrii/PycharmProjects/work_on_ship/venv/lib/python3.8/site-packages/flask/app.py:1891]
Traceback (most recent call last):
  File "/home/andrii/PycharmProjects/work_on_ship/venv/lib/python3.8/site-packages/flask/app.py", line 2447, in wsgi_app
    response = self.full_dispatch_request()
  File "/home/andrii/PycharmProjects/work_on_ship/venv/lib/python3.8/site-packages/flask/app.py", line 1952, in full_dispatch_request
    rv = self.handle_user_exception(e)
  File "/home/andrii/PycharmProjects/work_on_ship/venv/lib/python3.8/site-packages/flask/app.py", line 1821, in handle_user_exception
    reraise(exc_type, exc_value, tb)
  File "/home/andrii/PycharmProjects/work_on_ship/venv/lib/python3.8/site-packages/flask/_compat.py", line 39, in reraise
    raise value
  File "/home/andrii/PycharmProjects/work_on_ship/venv/lib/python3.8/site-packages/flask/app.py", line 1950, in full_dispatch_request
    rv = self.dispatch_request()
  File "/home/andrii/PycharmProjects/work_on_ship/venv/lib/python3.8/site-packages/flask/app.py", line 1936, in dispatch_request
    return self.view_functions[rule.endpoint](**req.view_args)
  File "/home/andrii/PycharmProjects/work_on_ship/app/routes.py", line 27, in index
    mail.send(msg)
  File "/home/andrii/PycharmProjects/work_on_ship/venv/lib/python3.8/site-packages/flask_mail.py", line 492, in send
    message.send(connection)
  File "/home/andrii/PycharmProjects/work_on_ship/venv/lib/python3.8/site-packages/flask_mail.py", line 427, in send
    connection.send(self)
  File "/home/andrii/PycharmProjects/work_on_ship/venv/lib/python3.8/site-packages/flask_mail.py", line 177, in send
    assert message.sender, (
AssertionError: The message does not specify a sender and a default sender has not been configured
2020-09-04 17:59:53,084 INFO: Work_on_ship startup [in /home/andrii/PycharmProjects/work_on_ship/app/__init__.py:46]
2020-09-04 18:00:04,535 ERROR: Exception on /index [POST] [in /home/andrii/PycharmProjects/work_on_ship/venv/lib/python3.8/site-packages/flask/app.py:1891]
Traceback (most recent call last):
  File "/home/andrii/PycharmProjects/work_on_ship/venv/lib/python3.8/site-packages/flask/app.py", line 2447, in wsgi_app
    response = self.full_dispatch_request()
  File "/home/andrii/PycharmProjects/work_on_ship/venv/lib/python3.8/site-packages/flask/app.py", line 1952, in full_dispatch_request
    rv = self.handle_user_exception(e)
  File "/home/andrii/PycharmProjects/work_on_ship/venv/lib/python3.8/site-packages/flask/app.py", line 1821, in handle_user_exception
    reraise(exc_type, exc_value, tb)
  File "/home/andrii/PycharmProjects/work_on_ship/venv/lib/python3.8/site-packages/flask/_compat.py", line 39, in reraise
    raise value
  File "/home/andrii/PycharmProjects/work_on_ship/venv/lib/python3.8/site-packages/flask/app.py", line 1950, in full_dispatch_request
    rv = self.dispatch_request()
  File "/home/andrii/PycharmProjects/work_on_ship/venv/lib/python3.8/site-packages/flask/app.py", line 1936, in dispatch_request
    return self.view_functions[rule.endpoint](**req.view_args)
  File "/home/andrii/PycharmProjects/work_on_ship/app/routes.py", line 27, in index
    mail.send(msg)
  File "/home/andrii/PycharmProjects/work_on_ship/venv/lib/python3.8/site-packages/flask_mail.py", line 492, in send
    message.send(connection)
  File "/home/andrii/PycharmProjects/work_on_ship/venv/lib/python3.8/site-packages/flask_mail.py", line 427, in send
    connection.send(self)
  File "/home/andrii/PycharmProjects/work_on_ship/venv/lib/python3.8/site-packages/flask_mail.py", line 181, in send
    if message.has_bad_headers():
  File "/home/andrii/PycharmProjects/work_on_ship/venv/lib/python3.8/site-packages/flask_mail.py", line 400, in has_bad_headers
    headers = [self.sender, self.reply_to] + self.recipients
TypeError: can only concatenate list (not "str") to list
2020-09-04 18:02:11,661 INFO: Work_on_ship startup [in /home/andrii/PycharmProjects/work_on_ship/app/__init__.py:46]
2020-09-04 18:02:25,704 ERROR: Exception on /index [POST] [in /home/andrii/PycharmProjects/work_on_ship/venv/lib/python3.8/site-packages/flask/app.py:1891]
Traceback (most recent call last):
  File "/home/andrii/PycharmProjects/work_on_ship/venv/lib/python3.8/site-packages/flask/app.py", line 2447, in wsgi_app
    response = self.full_dispatch_request()
  File "/home/andrii/PycharmProjects/work_on_ship/venv/lib/python3.8/site-packages/flask/app.py", line 1952, in full_dispatch_request
    rv = self.handle_user_exception(e)
  File "/home/andrii/PycharmProjects/work_on_ship/venv/lib/python3.8/site-packages/flask/app.py", line 1821, in handle_user_exception
    reraise(exc_type, exc_value, tb)
  File "/home/andrii/PycharmProjects/work_on_ship/venv/lib/python3.8/site-packages/flask/_compat.py", line 39, in reraise
    raise value
  File "/home/andrii/PycharmProjects/work_on_ship/venv/lib/python3.8/site-packages/flask/app.py", line 1950, in full_dispatch_request
    rv = self.dispatch_request()
  File "/home/andrii/PycharmProjects/work_on_ship/venv/lib/python3.8/site-packages/flask/app.py", line 1936, in dispatch_request
    return self.view_functions[rule.endpoint](**req.view_args)
  File "/home/andrii/PycharmProjects/work_on_ship/app/routes.py", line 27, in index
    mail.send(msg)
  File "/home/andrii/PycharmProjects/work_on_ship/venv/lib/python3.8/site-packages/flask_mail.py", line 492, in send
    message.send(connection)
  File "/home/andrii/PycharmProjects/work_on_ship/venv/lib/python3.8/site-packages/flask_mail.py", line 427, in send
    connection.send(self)
  File "/home/andrii/PycharmProjects/work_on_ship/venv/lib/python3.8/site-packages/flask_mail.py", line 181, in send
    if message.has_bad_headers():
  File "/home/andrii/PycharmProjects/work_on_ship/venv/lib/python3.8/site-packages/flask_mail.py", line 400, in has_bad_headers
    headers = [self.sender, self.reply_to] + self.recipients
TypeError: can only concatenate list (not "str") to list
2020-09-04 18:05:48,725 INFO: Work_on_ship startup [in /home/andrii/PycharmProjects/work_on_ship/app/__init__.py:46]
